2025-02-07 21:20:31.445 | INFO     | __main__:main:46 - Starting server, serving from directory /iopsstor/scratch/cscs/tkerimog/tinyllava/mixtera_server_2
2025-02-07 21:20:31.448 | DEBUG    | mixtera.core.client.mixtera_client:__init__:139 - Initialized current mixture id to -1.
2025-02-07 21:20:31.450 | INFO     | mixtera.core.datacollection.mixtera_data_collection:_load_db_from_disk:76 - Loading database from /iopsstor/scratch/cscs/tkerimog/tinyllava/mixtera_server_2/mixtera.duckdb
2025-02-07 21:20:31.489 | INFO     | mixtera.core.datacollection.mixtera_data_collection:_load_db_from_disk:78 - Database loaded.
2025-02-07 21:20:31.504 | INFO     | mixtera.core.datacollection.mixtera_data_collection:_vacuum:123 - Vacuuming the DuckDB.
2025-02-07 21:20:31.505 | INFO     | mixtera.core.datacollection.mixtera_data_collection:_vacuum:125 - Vacuumd.
2025-02-07 21:20:31.506 | DEBUG    | mixtera.core.query.query_cache:__init__:18 - Initializing QueryCache at /iopsstor/scratch/cscs/tkerimog/tinyllava/mixtera_server_2/querycache
2025-02-07 21:20:31.516 | INFO     | mixtera.network.server.server:_run_async:379 - Serving MixteraServer on ('172.28.33.16', 12345)
2025-02-07 21:20:33.548 | DEBUG    | mixtera.core.client.mixtera_client:__init__:139 - Initialized current mixture id to -1.
2025-02-07 21:20:33.556 | INFO     | mixtera.core.datacollection.index.parser.parser_collection:add_parser:219 - Registered medata parser GenericMetadataParser with the associated class <class 'mixtera.core.datacollection.index.parser.parser_collection.GenericMetadataParser'>
2025-02-07 21:20:34.075 | INFO     | mixtera.core.datacollection.mixtera_data_collection:_insert_dataset_into_table:242 - Successfully registered dataset LLAVA_FINETUNE with id 1.
2025-02-07 21:20:38.118 | INFO     | mixtera.core.datacollection.mixtera_data_collection:register_dataset:159 - Gathered 1 files, ready to insert
2025-02-07 21:20:38.123 | INFO     | mixtera.core.datacollection.mixtera_data_collection:register_dataset:164 - Columns added to samples table based on parser schema.
2025-02-07 21:20:38.146 | INFO     | mixtera.core.datacollection.mixtera_data_collection:_insert_files_into_table:253 - Inserting 1 files for dataset id = 1
2025-02-07 21:20:38.202 | INFO     | mixtera.core.datacollection.mixtera_data_collection:register_dataset:179 - Prepared tasks for reading
2025-02-07 21:20:45.458 | INFO     | mixtera.core.datacollection.mixtera_data_collection:register_dataset:192 - Processed chunk 1, inserting samples.
2025-02-07 21:20:45.584 | DEBUG    | mixtera.core.datacollection.mixtera_data_collection:_insert_samples_with_metadata:342 - Collected column-wise data for constructing pyarrow table.
Traceback (most recent call last):
  File "/usr/lib/python3.10/asyncio/streams.py", line 669, in read
    await self._wait_for_data('read')
  File "/usr/lib/python3.10/asyncio/streams.py", line 501, in _wait_for_data
    await self._waiter
asyncio.exceptions.CancelledError

During handling of the above exception, another exception occurred:

Traceback (most recent call last):
  File "/usr/lib/python3.10/asyncio/tasks.py", line 456, in wait_for
    return fut.result()
asyncio.exceptions.CancelledError

The above exception was the direct cause of the following exception:

Traceback (most recent call last):
  File "/iopsstor/scratch/cscs/tkerimog/tinyllava/mixtera/mixtera/network/connection/server_connection.py", line 118, in _connect_to_server
    yield reader, writer
  File "/iopsstor/scratch/cscs/tkerimog/tinyllava/mixtera/mixtera/network/connection/server_connection.py", line 355, in _register_dataset
    return bool(await read_int(NUM_BYTES_FOR_IDENTIFIERS, reader))
  File "/iopsstor/scratch/cscs/tkerimog/tinyllava/mixtera/mixtera/network/network_utils.py", line 128, in read_int
    if (bytes_data := await read_bytes(num_bytes, reader, timeout=timeout)) is not None
  File "/iopsstor/scratch/cscs/tkerimog/tinyllava/mixtera/mixtera/network/network_utils.py", line 34, in read_bytes
    chunk = await asyncio.wait_for(reader.read(num_bytes - len(buffer)), timeout=remaining_time)
  File "/usr/lib/python3.10/asyncio/tasks.py", line 458, in wait_for
    raise exceptions.TimeoutError() from exc
asyncio.exceptions.TimeoutError

During handling of the above exception, another exception occurred:

Traceback (most recent call last):
  File "/iopsstor/scratch/cscs/tkerimog/tinyllava/TinyLLaVA_Factory/register_dataset.py", line 34, in <module>
    client.register_dataset(finetune_dataset_name, finetune_dataset_path, LLaVADataset, parsing_func_finetune, "GenericMetadataParser")
  File "/iopsstor/scratch/cscs/tkerimog/tinyllava/mixtera/mixtera/core/client/server/server_stub.py", line 47, in register_dataset
    return self.server_connection.register_dataset(
  File "/iopsstor/scratch/cscs/tkerimog/tinyllava/mixtera/mixtera/network/connection/server_connection.py", line 307, in register_dataset
    return run_async_until_complete(
  File "/iopsstor/scratch/cscs/tkerimog/tinyllava/mixtera/mixtera/utils/utils.py", line 39, in run_async_until_complete
    return asyncio.run(call)
  File "/usr/lib/python3.10/asyncio/runners.py", line 44, in run
    return loop.run_until_complete(main)
  File "/usr/lib/python3.10/asyncio/base_events.py", line 649, in run_until_complete
    return future.result()
  File "/iopsstor/scratch/cscs/tkerimog/tinyllava/mixtera/mixtera/network/connection/server_connection.py", line 332, in _register_dataset
    async with self._connect_to_server() as (reader, writer):
  File "/usr/lib/python3.10/contextlib.py", line 249, in __aexit__
    raise RuntimeError("generator didn't stop after athrow()")
RuntimeError: generator didn't stop after athrow()
2025-02-07 21:20:45.627 | DEBUG    | mixtera.core.datacollection.mixtera_data_collection:_insert_samples_with_metadata:366 - Constructed PyArrow Table.
2025-02-07 21:20:45.874 | DEBUG    | mixtera.core.datacollection.mixtera_data_collection:_insert_samples_with_metadata:375 - Data inserted successfully.
2025-02-07 21:20:45.930 | INFO     | mixtera.core.datacollection.mixtera_data_collection:register_dataset:195 - All tasks finished.
2025-02-07 21:20:46.021 | INFO     | mixtera.core.datacollection.mixtera_data_collection:_vacuum:123 - Vacuuming the DuckDB.
2025-02-07 21:20:46.021 | INFO     | mixtera.core.datacollection.mixtera_data_collection:_vacuum:125 - Vacuumd.
2025-02-07 21:20:46.021 | INFO     | mixtera.core.datacollection.mixtera_data_collection:register_dataset:200 - Finished dataset registration.
2025-02-07 21:20:46.047 | ERROR    | mixtera.network.server.server:_dispatch_client:359 - Some exception occured while handling client request: Unknown task id: None
2025-02-07 21:20:46.048 | ERROR    | mixtera.network.server.server:_dispatch_client:360 - Unknown task id: None
Traceback (most recent call last):

  File "/usr/lib/python3.10/runpy.py", line 196, in _run_module_as_main
    return _run_code(code, main_globals, None,
           │         │     └ {'__name__': '__main__', '__doc__': None, '__package__': 'mixtera.network.server', '__loader__': <_frozen_importlib_external....
           │         └ <code object <module> at 0x400195635370, file "/iopsstor/scratch/cscs/tkerimog/tinyllava/mixtera/mixtera/network/server/entry...
           └ <function _run_code at 0x400012293d90>
  File "/usr/lib/python3.10/runpy.py", line 86, in _run_code
    exec(code, run_globals)
         │     └ {'__name__': '__main__', '__doc__': None, '__package__': 'mixtera.network.server', '__loader__': <_frozen_importlib_external....
         └ <code object <module> at 0x400195635370, file "/iopsstor/scratch/cscs/tkerimog/tinyllava/mixtera/mixtera/network/server/entry...

  File "/iopsstor/scratch/cscs/tkerimog/tinyllava/mixtera/mixtera/network/server/entrypoint.py", line 55, in <module>
    main()
    └ <function main at 0x400195640e50>

  File "/iopsstor/scratch/cscs/tkerimog/tinyllava/mixtera/mixtera/network/server/entrypoint.py", line 49, in main
    server.run()
    │      └ <function MixteraServer.run at 0x400195640d30>
    └ <mixtera.network.server.server.MixteraServer object at 0x400012073af0>

  File "/iopsstor/scratch/cscs/tkerimog/tinyllava/mixtera/mixtera/network/server/server.py", line 399, in run
    asyncio.run(self._run_async())
    │       │   │    └ <function MixteraServer._run_async at 0x400195640ca0>
    │       │   └ <mixtera.network.server.server.MixteraServer object at 0x400012073af0>
    │       └ <function run at 0x4000122ace50>
    └ <module 'asyncio' from '/usr/lib/python3.10/asyncio/__init__.py'>

  File "/usr/lib/python3.10/asyncio/runners.py", line 44, in run
    return loop.run_until_complete(main)
           │    │                  └ <coroutine object MixteraServer._run_async at 0x400194b1e500>
           │    └ <function BaseEventLoop.run_until_complete at 0x400012a237f0>
           └ <_UnixSelectorEventLoop running=True closed=False debug=False>
  File "/usr/lib/python3.10/asyncio/base_events.py", line 636, in run_until_complete
    self.run_forever()
    │    └ <function BaseEventLoop.run_forever at 0x400012a23760>
    └ <_UnixSelectorEventLoop running=True closed=False debug=False>
  File "/usr/lib/python3.10/asyncio/base_events.py", line 603, in run_forever
    self._run_once()
    │    └ <function BaseEventLoop._run_once at 0x400012a292d0>
    └ <_UnixSelectorEventLoop running=True closed=False debug=False>
  File "/usr/lib/python3.10/asyncio/base_events.py", line 1909, in _run_once
    handle._run()
    │      └ <function Handle._run at 0x4000129c4ca0>
    └ <Handle Task.task_wakeup(<Future finished result=None>)>
  File "/usr/lib/python3.10/asyncio/events.py", line 80, in _run
    self._context.run(self._callback, *self._args)
    │    │            │    │           │    └ <member '_args' of 'Handle' objects>
    │    │            │    │           └ <Handle Task.task_wakeup(<Future finished result=None>)>
    │    │            │    └ <member '_callback' of 'Handle' objects>
    │    │            └ <Handle Task.task_wakeup(<Future finished result=None>)>
    │    └ <member '_context' of 'Handle' objects>
    └ <Handle Task.task_wakeup(<Future finished result=None>)>

> File "/iopsstor/scratch/cscs/tkerimog/tinyllava/mixtera/mixtera/network/server/server.py", line 322, in _dispatch_client
    raise RuntimeError(f"Unknown task id: {task_int}")

RuntimeError: Unknown task id: None
